
Running tests... 
----------------------------------------------------------------------
 test_api_1 (test_case.test_http_request.TestHttpRequest) ... ERROR (0.358003)s
 test_api_2 (test_case.test_http_request.TestHttpRequest) ... OK (0.288007)s
 test_api_3 (test_case.test_http_request.TestHttpRequest) ... OK (0.310958)s
 test_api_4 (test_case.test_http_request.TestHttpRequest) ... OK (0.300036)s
 test_api_5 (test_case.test_http_request.TestHttpRequest) ... OK (0.282999)s
 test_api_6 (test_case.test_http_request.TestHttpRequest) ... OK (0.297997)s
 test_api_7 (test_case.test_http_request.TestHttpRequest) ... ERROR (0.000000)s
 test_api_8 (test_case.test_http_request.TestHttpRequest) ... ERROR (0.000995)s

======================================================================
ERROR [0.358003s]: test_case.test_http_request.TestHttpRequest.test_api_1
----------------------------------------------------------------------
Traceback (most recent call last):
  File "E:\python372\lib\site-packages\ddt.py", line 182, in wrapper
    return func(self, *args, **kwargs)
  File "d:\programming\testing\unittest_api_demo\test_case\test_http_request.py", line 34, in test_api
    self.assertEqual(item['expected'],res.json()['info'])
KeyError: 'info'
E:\python372\lib\site-packages\urllib3\connectionpool.py:986: InsecureRequestWarning: Unverified HTTPS request is being made to host 'www.ketangpai.com'. Adding certificate verification is strongly advised. See: https://urllib3.readthedocs.io/en/latest/advanced-usage.html#ssl-warnings
  InsecureRequestWarning,

======================================================================
ERROR [0.000000s]: test_case.test_http_request.TestHttpRequest.test_api_7
----------------------------------------------------------------------
Traceback (most recent call last):
  File "E:\python372\lib\site-packages\ddt.py", line 182, in wrapper
    return func(self, *args, **kwargs)
  File "d:\programming\testing\unittest_api_demo\test_case\test_http_request.py", line 28, in test_api
    eval(item['data']),
TypeError: eval() arg 1 must be a string, bytes or code object

======================================================================
ERROR [0.000995s]: test_case.test_http_request.TestHttpRequest.test_api_8
----------------------------------------------------------------------
Traceback (most recent call last):
  File "E:\python372\lib\site-packages\ddt.py", line 182, in wrapper
    return func(self, *args, **kwargs)
  File "d:\programming\testing\unittest_api_demo\test_case\test_http_request.py", line 28, in test_api
    eval(item['data']),
TypeError: eval() arg 1 must be a string, bytes or code object

----------------------------------------------------------------------
Ran 8 tests in 0:00:01

FAILED
 (Errors=3)

Generating HTML reports... 
report\test_api测试报告_test_case.test_http_request.TestHttpRequest.html
